<?xml version="1.0" ?>
<!-- =================================================================================== -->
<!-- |    This document was autogenerated by xacro from my_robot.xacro                 | -->
<!-- |    EDITING THIS FILE BY HAND IS NOT RECOMMENDED                                 | -->
<!-- =================================================================================== -->
<robot name="my_robot">
  <gazebo>
    <plugin filename="libgazebo_ros_diff_drive.so" name="differential_drive_controller">
      <legacyMode>false</legacyMode>
      <alwaysOn>true</alwaysOn>
      <updateRate>10</updateRate>
      <leftJoint>mid_left_wheel_hinge</leftJoint>
      <rightJoint>mid_right_wheel_hinge</rightJoint>
      <wheelSeparation>0.4</wheelSeparation>
      <wheelDiameter>0.2</wheelDiameter>
      <torque>10</torque>
      <commandTopic>cmd_vel</commandTopic>
      <odometryTopic>odom</odometryTopic>
      <odometryFrame>odom</odometryFrame>
      <robotBaseFrame>robot_footprint</robotBaseFrame>
      <publishWheelTF>false</publishWheelTF>
      <publishWheelJointState>false</publishWheelJointState>
      <rosDebugLevel>na</rosDebugLevel>
      <wheelAcceleration>0</wheelAcceleration>
      <wheelTorque>5</wheelTorque>
      <odometrySource>world</odometrySource>
      <publishTf>1</publishTf>
      <publishOdomTF>true</publishOdomTF>
    </plugin>
  </gazebo>
  <link name="robot_footprint"/>
  <joint name="robot_footprint_joint" type="fixed">
    <origin rpy="0 0 0" xyz="0 0 0.15"/>
    <parent link="robot_footprint"/>
    <child link="chassis"/>
  </joint>
  <link name="chassis">
    <pose>0 0 0.1 0 0 0</pose>
    <inertial>
      <mass value="30.0"/>
      <origin rpy=" 0 0 0" xyz="0.0 0 0"/>
      <inertia ixx="0.1" ixy="0" ixz="0" iyy="0.1" iyz="0" izz="0.1"/>
    </inertial>
    <collision name="collision">
      <origin rpy=" 0 0 0" xyz="0 0 0"/>
      <geometry>
        <box size=".4 .3 .15"/>
      </geometry>
      <material name="green">
        <color rgba="0.0 1.0 0.0 1.0"/>
      </material>
    </collision>
    <visual name="chassis_visual">
      <origin rpy=" 0 0 0" xyz="0 0 0"/>
      <geometry>
        <box size=".4 .3 .15"/>
      </geometry>
      <material name="green">
        <color rgba="0.0 1.0 0.0 1.0"/>
      </material>
    </visual>
    <collision name="back_caster_collision">
      <origin rpy=" 0 0 0" xyz="-0.1 0 -0.075"/>
      <geometry>
        <sphere radius="0.073"/>
      </geometry>
    </collision>
    <visual name="back_caster_visual">
      <origin rpy=" 0 0 0" xyz="-0.1 0 -0.075"/>
      <geometry>
        <sphere radius="0.075"/>
      </geometry>
    </visual>
    <collision name="front_caster_collision">
      <origin rpy=" 0 0 0" xyz="0.1 0 -0.075"/>
      <geometry>
        <sphere radius="0.073"/>
      </geometry>
    </collision>
    <visual name="front_caster_visual">
      <origin rpy=" 0 0 0" xyz="0.1 0 -0.075"/>
      <geometry>
        <sphere radius="0.075"/>
      </geometry>
    </visual>
  </link>
  <gazebo reference="chassis">
    <material>Gazebo/Green</material>
  </gazebo>
  <joint name="mid_right_wheel_hinge" type="continuous">
    <origin rpy="0 0 0" xyz="0 -0.2 0"/>
    <parent link="chassis"/>
    <child link="mid_right_wheel"/>
    <axis rpy="0 0 0" xyz="0 1 0"/>
    <limit effort="10000" velocity="1000"/>
    <dynamics damping="1.0" friction="1.0"/>
  </joint>
  <link name="mid_right_wheel">
    <pose>0 0 0.1 0 0 0</pose>
    <inertial>
      <mass value="10.0"/>
      <origin rpy=" 0 1.5707 1.5707" xyz="0 0 0"/>
      <inertia ixx="0.1" ixy="0" ixz="0" iyy="0.1" iyz="0" izz="0.1"/>
    </inertial>
    <collision name="mid_right_wheel_collision">
      <origin rpy=" 0 1.5707 1.5707" xyz="0 0 0"/>
      <geometry>
        <cylinder length=".05" radius=".15"/>
      </geometry>
      <material name="black">
        <color rgba="0.0 0.0 0.0 1.0"/>
      </material>
    </collision>
    <visual name="mid_right_wheel_visual">
      <origin rpy=" 0 1.5707 1.5707" xyz="0 0 0"/>
      <geometry>
        <cylinder length=".05" radius=".15"/>
      </geometry>
      <material name="black">
        <color rgba="0.0 0.0 0.0 1.0"/>
      </material>
    </visual>
  </link>
  <gazebo reference="mid_right_wheel">
    <material>Gazebo/Black</material>
  </gazebo>
  <joint name="mid_left_wheel_hinge" type="continuous">
    <origin rpy="0 0 0" xyz="0 0.2 0"/>
    <parent link="chassis"/>
    <child link="mid_left_wheel"/>
    <axis rpy="0 0 0" xyz="0 1 0"/>
    <limit effort="10000" velocity="1000"/>
    <dynamics damping="1.0" friction="1.0"/>
  </joint>
  <link name="mid_left_wheel">
    <pose>0 0 0.1 0 0 0</pose>
    <inertial>
      <mass value="10.0"/>
      <origin rpy=" 0 1.5707 1.5707" xyz="0 0 0"/>
      <inertia ixx="0.1" ixy="0" ixz="0" iyy="0.1" iyz="0" izz="0.1"/>
    </inertial>
    <collision name="mid_left_wheel_collision">
      <origin rpy=" 0 1.5707 1.5707" xyz="0 0 0"/>
      <geometry>
        <cylinder length=".05" radius=".15"/>
      </geometry>
      <material name="black">
        <color rgba="0.0 0.0 0.0 1.0"/>
      </material>
    </collision>
    <visual name="mid_left_wheel_visual">
      <origin rpy=" 0 1.5707 1.5707" xyz="0 0 0"/>
      <geometry>
        <cylinder length=".05" radius=".15"/>
      </geometry>
      <material name="black">
        <color rgba="0.0 0.0 0.0 1.0"/>
      </material>
    </visual>
  </link>
  <gazebo reference="mid_left_wheel">
    <material>Gazebo/Black</material>
  </gazebo>
</robot>
